============================= test session starts ==============================
platform linux -- Python 3.10.6, pytest-7.3.1, pluggy-1.0.0
rootdir: /data/sandeep/leetcode-master/.verifaiws
collected 1 item

628_Maximum_Product_of_Three_Numbers/test_628_Maximum_Product_of_Three_Numbers.py F [100%]

=================================== FAILURES ===================================
_____________________________ test_maximum_product _____________________________

    def test_maximum_product():
        # Test case 1
        s = Solution()
        nums = [1,2,3,4]
        expected_output = 24
        assert s.maximumProduct(nums) == expected_output
    
        # Test case 2
        s = Solution()
        nums = [-1,-2,-3,-4,-5]
        expected_output = -6
        assert s.maximumProduct(nums) == expected_output
    
        # Test case 3
        s = Solution()
        nums = [-1,-2,3,4,5]
        expected_output = 40
>       assert s.maximumProduct(nums) == expected_output
E       assert 60 == 40
E        +  where 60 = <bound method Solution.maximumProduct of <solution.Solution object at 0x7fa10ab80460>>([-1, -2, 3, 4, 5])
E        +    where <bound method Solution.maximumProduct of <solution.Solution object at 0x7fa10ab80460>> = <solution.Solution object at 0x7fa10ab80460>.maximumProduct

628_Maximum_Product_of_Three_Numbers/test_628_Maximum_Product_of_Three_Numbers.py:22: AssertionError
=========================== short test summary info ============================
FAILED 628_Maximum_Product_of_Three_Numbers/test_628_Maximum_Product_of_Three_Numbers.py::test_maximum_product
============================== 1 failed in 0.01s ===============================
