============================= test session starts ==============================
platform linux -- Python 3.10.6, pytest-7.3.1, pluggy-1.0.0
rootdir: /data/sandeep/leetcode-master/.verifaiws
collected 1 item

414_Third_Maximum_Number/test_414_Third_Maximum_Number.py F              [100%]

=================================== FAILURES ===================================
__________________________ TestSolution.test_thirdMax __________________________

self = <test_414_Third_Maximum_Number.TestSolution object at 0x7f1909500370>

    def test_thirdMax(self):
      sol = Solution()
    
      nums1 = [3, 2, 1]
      assert sol.thirdMax(nums1) == 1
    
      nums2 = [1, 2]
>     assert sol.thirdMax(nums2) == 2
E     assert 1 == 2
E      +  where 1 = <bound method Solution.thirdMax of <solution.Solution object at 0x7f1909500460>>([1, 2])
E      +    where <bound method Solution.thirdMax of <solution.Solution object at 0x7f1909500460>> = <solution.Solution object at 0x7f1909500460>.thirdMax

414_Third_Maximum_Number/test_414_Third_Maximum_Number.py:12: AssertionError
=========================== short test summary info ============================
FAILED 414_Third_Maximum_Number/test_414_Third_Maximum_Number.py::TestSolution::test_thirdMax
============================== 1 failed in 0.02s ===============================
