============================= test session starts ==============================
platform linux -- Python 3.10.6, pytest-7.3.1, pluggy-1.0.0
rootdir: /data/sandeep/leetcode-master/.verifaiws
collected 3 items

062_Unique_Paths/test_062_Unique_Paths.py F.F                            [100%]

=================================== FAILURES ===================================
_______________________________ test_uniquePaths _______________________________

    def test_uniquePaths():
        s = Solution()
        assert s.uniquePaths(3, 3) == 6
        assert s.uniquePaths(7, 3) == 28
        assert s.uniquePaths(3, 7) == 28
        assert s.uniquePaths(1, 1) == 1
        assert s.uniquePaths(1, 10) == 1
        assert s.uniquePaths(5, 5) == 70
>       assert s.uniquePaths(0, 0) == 0

062_Unique_Paths/test_062_Unique_Paths.py:13: 
_ _ _ _ _ _ _ _ _ _ _ _ _ _ _ _ _ _ _ _ _ _ _ _ _ _ _ _ _ _ _ _ _ _ _ _ _ _ _ _ 

self = <solution.Solution object at 0x7f63f27c46a0>, m = 0, n = 0

    def uniquePaths(self, m, n):
        """
        :type m: int
        :type n: int
        :rtype: int
        """
        dmap = [[0] * n for _ in range(m)]
        for i in range(m):
            dmap[i][0] = 1
        for j in range(n):
            dmap[0][j] = 1
        for i in range(1, m):
            for j in range(1, n):
                l = u = 0
                if i-1 >= 0:
                    u = dmap[i-1][j]
                if j-1>= 0:
                    l = dmap[i][j-1]
                dmap[i][j] = l + u
>       return dmap[m-1][n-1]
E       IndexError: list index out of range

062_Unique_Paths/solution.py:21: IndexError
______________________ test_uniquePaths_raises_ValueError ______________________

    def test_uniquePaths_raises_ValueError():
        s = Solution()
        with pytest.raises(ValueError):
>           s.uniquePaths(-1, 3)

062_Unique_Paths/test_062_Unique_Paths.py:32: 
_ _ _ _ _ _ _ _ _ _ _ _ _ _ _ _ _ _ _ _ _ _ _ _ _ _ _ _ _ _ _ _ _ _ _ _ _ _ _ _ 

self = <solution.Solution object at 0x7f63f27c4ee0>, m = -1, n = 3

    def uniquePaths(self, m, n):
        """
        :type m: int
        :type n: int
        :rtype: int
        """
        dmap = [[0] * n for _ in range(m)]
        for i in range(m):
            dmap[i][0] = 1
        for j in range(n):
>           dmap[0][j] = 1
E           IndexError: list index out of range

062_Unique_Paths/solution.py:12: IndexError
=========================== short test summary info ============================
FAILED 062_Unique_Paths/test_062_Unique_Paths.py::test_uniquePaths - IndexErr...
FAILED 062_Unique_Paths/test_062_Unique_Paths.py::test_uniquePaths_raises_ValueError
========================= 2 failed, 1 passed in 0.02s ==========================
